#VRML_SIM R2023a utf8

EXTERNPROTO "https://raw.githubusercontent.com/cyberbotics/webots/R2023a/projects/objects/backgrounds/protos/TexturedBackground.proto"
EXTERNPROTO "https://raw.githubusercontent.com/cyberbotics/webots/R2023a/projects/objects/backgrounds/protos/TexturedBackgroundLight.proto"
EXTERNPROTO "https://raw.githubusercontent.com/cyberbotics/webots/R2023a/projects/objects/floors/protos/RectangleArena.proto"
EXTERNPROTO "https://raw.githubusercontent.com/cyberbotics/webots/R2023a/projects/appearances/protos/TireRubber.proto"
EXTERNPROTO "https://raw.githubusercontent.com/cyberbotics/webots/R2023a/projects/appearances/protos/OsbWood.proto"

WorldInfo {
  basicTimeStep 16
}
Viewpoint {
  orientation -0.6950363424885935 -0.010583989079353009 0.7188966975826546 3.1634905147977683
  position -1.6895268152317526 0.912958537946645 9.388458324948918
  follow "robot_clone"
  followType "None"
  followSmoothness 0.01
}
TexturedBackground {
}
TexturedBackgroundLight {
}
RectangleArena {
  contactMaterial "floor"
  floorSize 7 4.55
  wallThickness 0.1
}
DEF waypoints Transform {
  translation 0 0 0.22
  children [
    Transform {
      translation 1.61 -1.13 0
      rotation 0 1 0 0
      children [
        Shape {
          geometry Sphere {
            radius 0.05
          }
        }
      ]
    }
    Transform {
      translation 0.83 -0.95 0
      rotation 0 1 0 0
      children [
        Shape {
          geometry Sphere {
            radius 0.05
          }
        }
      ]
    }
    Transform {
      translation -0.08 -0.91 0
      rotation 0 1 0 0
      children [
        Shape {
          geometry Sphere {
            radius 0.05
          }
        }
      ]
    }
    Transform {
      translation -0.35 -0.46 0
      rotation 0 1 0 0
      children [
        Shape {
          geometry Sphere {
            radius 0.05
          }
        }
      ]
    }
    Transform {
      translation -0.55 0.34 0
      rotation 0 1 0 0
      children [
        Shape {
          geometry Sphere {
            radius 0.05
          }
        }
      ]
    }
    Transform {
      translation -0.92 0.88 0
      rotation 0 1 0 0
      children [
        Shape {
          geometry Sphere {
            radius 0.05
          }
        }
      ]
    }
    Transform {
      translation -1.46 1.1 0
      rotation 0 1 0 0
      children [
        Shape {
          geometry Sphere {
            radius 0.05
          }
        }
      ]
    }
    Transform {
      translation -2.17 1.1 0
      rotation 0 1 0 0
      children [
        Shape {
          geometry Sphere {
            radius 0.05
          }
        }
      ]
    }
    Transform {
      translation -2.67 0.5 0
      rotation 0 1 0 0
      children [
        Shape {
          geometry Sphere {
            radius 0.05
          }
        }
      ]
    }
    Transform {
      translation -2.67 -0.13 0
      rotation 0 1 0 0
      children [
        Shape {
          geometry Sphere {
            radius 0.05
          }
        }
      ]
    }
    Transform {
      translation -2.41 -0.92 0
      rotation 0 1 0 0
      children [
        Shape {
          geometry Sphere {
            radius 0.05
          }
        }
      ]
    }
    Transform {
      translation -1.8 -1.36 0
      rotation 0 1 0 0
      children [
        Shape {
          geometry Sphere {
            radius 0.05
          }
        }
      ]
    }
    Transform {
      translation -1.13 -1.6 0
      rotation 0 1 0 0
      children [
        Shape {
          geometry Sphere {
            radius 0.05
          }
        }
      ]
    }
    Transform {
      translation -0.4 -1.74 0
      rotation 0 1 0 0
      children [
        Shape {
          geometry Sphere {
            radius 0.05
          }
        }
      ]
    }
    Transform {
      translation 0.38 -1.74 0
      rotation 0 1 0 0
      children [
        Shape {
          geometry Sphere {
            radius 0.05
          }
        }
      ]
    }
    Transform {
      translation 1.14 -1.73 0
      rotation 0 1 0 0
      children [
        Shape {
          geometry Sphere {
            radius 0.05
          }
        }
      ]
    }
  ]
}
Robot {
  translation 1.4198814588858568 -0.5002012668202082 0.039095298125070344
  rotation 0.8616447857961175 -0.5075118074629829 0.00016851118434721145 0.005953197161493884
  children [
    Camera {
      translation -0.09 0 0
      rotation 0 0 1 3.14159
      width 300
      height 150
    }
    Group {
      children [
        Transform {
          translation 0.05 0 0
          children [
            DEF pi Shape {
              appearance PBRAppearance {
                baseColor 0 0 0
              }
              geometry Box {
                size 0.09 0.051 0.03
              }
            }
          ]
        }
        Transform {
          translation 0 0 -0.02
          children [
            DEF base Shape {
              appearance PBRAppearance {
                baseColor 0 0 0
              }
              geometry Box {
                size 0.2 0.06 0.02
              }
            }
          ]
        }
      ]
    }
    DEF front_right_hinge Hinge2Joint {
      jointParameters HingeJointParameters {
        position 9.059157534508722e-12
        axis 0 0 1
        anchor -0.0645468 0.04 -0.0267332
      }
      jointParameters2 JointParameters {
        position -4.900524709928763e-06
        axis 0 1 0
      }
      device [
        DEF FRServo RotationalMotor {
          name "front_right_servo"
        }
      ]
      endPoint Solid {
        translation -0.0645468 0.04 -0.0267332
        rotation 0.9999999999939964 -2.450248825071192e-06 2.4502668845174387e-06 1.5708000000058737
        children [
          DEF front_left_wheel_shape Shape {
            appearance TireRubber {
            }
            geometry Cylinder {
              height 0.01
              radius 0.0125
            }
          }
        ]
        name "solid(2)"
        contactMaterial "tyre"
        boundingObject USE front_left_wheel_shape
        physics Physics {
        }
      }
    }
    DEF front_left_hinge Hinge2Joint {
      jointParameters HingeJointParameters {
        position -3.466773824720521e-11
        axis 0 0 1
        anchor -0.0645456 -0.04 -0.0261826
      }
      jointParameters2 JointParameters {
        position 0.003150144181398104
        axis 0 1 0
      }
      device [
        DEF FLServo RotationalMotor {
          name "front_left_servo"
        }
      ]
      endPoint Solid {
        translation -0.0645456 -0.04 -0.0261826
        rotation 0.9999874541523032 -0.003542244885695004 -0.0035417565083768463 4.712374653398543
        children [
          DEF front_right_wheel_shape Shape {
            appearance TireRubber {
            }
            geometry Cylinder {
              height 0.01
              radius 0.0125
            }
          }
        ]
        name "solid(3)"
        contactMaterial "tyre"
        boundingObject USE front_right_wheel_shape
        physics Physics {
        }
      }
    }
    DEF rear_right_hinge HingeJoint {
      jointParameters HingeJointParameters {
        axis 0 -1 0
        anchor 0.0754532 0.04 -0.0267332
      }
      device [
        RotationalMotor {
          name "right_wheel_motor"
          acceleration 5
          maxVelocity 100
        }
      ]
      endPoint Solid {
        translation 0.0754532 0.04 -0.0267332
        rotation 1 -5.06980743976947e-12 5.069826062246155e-12 1.5708
        children [
          DEF rear_right_wheel_shape Shape {
            appearance TireRubber {
            }
            geometry Cylinder {
              height 0.01
              radius 0.0125
            }
          }
        ]
        contactMaterial "tyre"
        boundingObject USE rear_right_wheel_shape
        physics Physics {
        }
      }
    }
    DEF rear_left_hinge HingeJoint {
      jointParameters HingeJointParameters {
        position 2.4342635535581548e-09
        axis 0 -1 0
        anchor 0.0754531317196739 -0.04000000620125117 -0.026733221149208525
      }
      device [
        DEF left_wheel_motor RotationalMotor {
          name "left_wheel_motor"
          acceleration 5
          maxVelocity 100
        }
      ]
      endPoint Solid {
        translation 0.0754531317196739 -0.04000000620125117 -0.026733221149208525
        rotation 0.9999961310880752 -0.0019671986448846165 -0.0019667074954375996 4.712383331184583
        children [
          DEF rear_left_wheel_shape Shape {
            appearance TireRubber {
            }
            geometry Cylinder {
              height 0.01
              radius 0.0125
            }
          }
        ]
        name "solid(1)"
        contactMaterial "tyre"
        boundingObject USE rear_left_wheel_shape
        physics Physics {
        }
      }
    }
  ]
  boundingObject Transform {
    translation 0 0 -0.005
    children [
      Box {
        size 0.2 0.06 0.05
      }
    ]
  }
  physics Physics {
  }
}
Robot {
  translation -2.55924 0.598699 0.0391349
  rotation 7.211039981070631e-05 -7.0850699814013085e-06 -0.999999997374946 -1.5708053071795867
  children [
    Lidar {
      translation -0.07 0 0
      rotation 0 0 1 3.14159
      horizontalResolution 6
      fieldOfView 2
      numberOfLayers 1
      maxRange 3
      projection "planar"
    }
    Camera {
      translation -0.09 0 0
      rotation 0 0 1 3.14159
      width 300
      height 150
    }
    Group {
      children [
        Transform {
          translation 0.05 0 0
          children [
            Shape {
              appearance PBRAppearance {
                baseColor 0.333333 0.333333 1
                metalness 0.8
              }
              geometry Box {
                size 0.09 0.051 0.03
              }
            }
          ]
        }
        Transform {
          translation 0 0 -0.02
          children [
            DEF base Shape {
              appearance PBRAppearance {
                baseColor 0.333333 0.333333 1
                metalness 0.8
              }
              geometry Box {
                size 0.2 0.06 0.02
              }
            }
          ]
        }
      ]
    }
    DEF front_right_hinge HingeJoint {
      jointParameters HingeJointParameters {
        position -0.4999999999485807
        axis 0 0 1
        anchor -0.0645468 0.04 -0.0267332
      }
      device [
        DEF FRServo RotationalMotor {
          name "front_right_servo"
        }
      ]
      endPoint Solid {
        translation -0.0645468 0.04 -0.0267332
        rotation 0 0 -1 0.49999999994858096
        children [
          HingeJoint {
            jointParameters HingeJointParameters {
              position -8718.655909397457
              axis 0 1 0
            }
            endPoint Solid {
              rotation 0 0.9999999999999999 0 2.405296967808595
              children [
                DEF wheel_shape Transform {
                  rotation 1 0 0 -1.5707953071795862
                  children [
                    Shape {
                      appearance TireRubber {
                      }
                      geometry Cylinder {
                        height 0.01
                        radius 0.0125
                      }
                    }
                  ]
                }
              ]
              boundingObject USE wheel_shape
              physics Physics {
              }
            }
          }
        ]
        boundingObject Box {
          size 0.01 0.01 0.01
        }
        physics Physics {
        }
      }
    }
    DEF front_left_hinge HingeJoint {
      jointParameters HingeJointParameters {
        position -0.49999999994865174
        axis 0 0 1
        anchor -0.0645468 -0.04 -0.0267332
      }
      device [
        DEF FLServo RotationalMotor {
          name "front_left_servo"
        }
      ]
      endPoint Solid {
        translation -0.0645468 -0.04 -0.0267332
        rotation 0 0 -1 0.49999999994865185
        children [
          HingeJoint {
            jointParameters HingeJointParameters {
              position -8303.345613933969
              axis 0 1 0
            }
            endPoint Solid {
              rotation 0 1 0 3.0253621574446155
              children [
                DEF wheel_shape Transform {
                  rotation 1 0 0 -1.5707953071795862
                  children [
                    Shape {
                      appearance TireRubber {
                      }
                      geometry Cylinder {
                        height 0.01
                        radius 0.0125
                      }
                    }
                  ]
                }
              ]
              boundingObject USE wheel_shape
              physics Physics {
              }
            }
          }
        ]
        name "solid(1)"
        boundingObject Box {
          size 0.01 0.01 0.01
        }
        physics Physics {
        }
      }
    }
    DEF rear_right_hinge HingeJoint {
      jointParameters HingeJointParameters {
        position 19209.51296115495
        axis 0 -1 0
        anchor 0.0754532 0.04 -0.0267332
      }
      device [
        RotationalMotor {
          name "right_wheel_motor"
          maxVelocity 100
        }
      ]
      endPoint Solid {
        translation 0.0754532 0.04 -0.0267332
        rotation 0 0.9999999999999999 0 4.467708200226293
        children [
          DEF wheel_shape Transform {
            rotation 1 0 0 -1.5707953071795862
            children [
              Shape {
                appearance TireRubber {
                }
                geometry Cylinder {
                  height 0.01
                  radius 0.0125
                }
              }
            ]
          }
        ]
        name "solid(2)"
        contactMaterial "tyre"
        boundingObject USE wheel_shape
        physics Physics {
        }
      }
    }
    DEF rear_left_hinge HingeJoint {
      jointParameters HingeJointParameters {
        position 19209.512949393662
        axis 0 -1 0
        anchor 0.0754532 -0.04 -0.0267332
      }
      device [
        RotationalMotor {
          name "left_wheel_motor"
          maxVelocity 100
        }
      ]
      endPoint Solid {
        translation 0.0754532 -0.04 -0.0267332
        rotation 0 1 0 4.467719961513462
        children [
          DEF wheel_shape Transform {
            rotation 1 0 0 -1.5707953071795862
            children [
              Shape {
                appearance TireRubber {
                }
                geometry Cylinder {
                  height 0.01
                  radius 0.0125
                }
              }
            ]
          }
        ]
        name "solid(3)"
        contactMaterial "tyre"
        boundingObject USE wheel_shape
        physics Physics {
        }
      }
    }
  ]
  name "robot_clone"
  boundingObject Transform {
    translation 0 0 -0.005
    children [
      Box {
        size 0.2 0.06 0.05
      }
    ]
  }
  physics Physics {
  }
  controller "robotSupervisorController"
  supervisor TRUE
}
DEF Track Transform {
  children [
    Solid {
      translation 1.19 -2.05 0.02
      children [
        DEF track1-bounding Shape {
          appearance OsbWood {
          }
          geometry Box {
            size 1.2 0.006 0.05
          }
        }
      ]
      name "solid(2)"
      boundingObject USE track1-bounding
    }
    Solid {
      translation -0.01 -2.05 0.02
      children [
        DEF track1-bounding Shape {
          appearance OsbWood {
          }
          geometry Box {
            size 1.2 0.006 0.05
          }
        }
      ]
      name "solid(1)"
      boundingObject USE track1-bounding
    }
    Solid {
      translation -1.21 -2.05 0.02
      children [
        DEF track1-bounding Shape {
          appearance OsbWood {
          }
          geometry Box {
            size 1.2 0.006 0.05
          }
        }
      ]
      name "solid(3)"
      boundingObject USE track1-bounding
    }
    Solid {
      translation -2.23826 -1.61746 0.02
      rotation 0 0 1 -0.785395307179586
      children [
        DEF track1-bounding Shape {
          appearance OsbWood {
          }
          geometry Box {
            size 1.2 0.006 0.05
          }
        }
      ]
      name "solid(4)"
      boundingObject USE track1-bounding
    }
    Solid {
      translation -2.96198 -0.6752 0.02
      rotation 0 0 1 -1.047195307179586
      children [
        DEF track1-bounding Shape {
          appearance OsbWood {
          }
          geometry Box {
            size 1.2 0.006 0.05
          }
        }
      ]
      name "solid(5)"
      boundingObject USE track1-bounding
    }
    Solid {
      translation -3.26698 0.441746 0.02
      rotation 0 0 1 1.5708
      children [
        DEF track1-bounding Shape {
          appearance OsbWood {
          }
          geometry Box {
            size 1.2 0.006 0.05
          }
        }
      ]
      name "solid(6)"
      boundingObject USE track1-bounding
    }
    Solid {
      translation -2.84278 1.45277 0.02
      rotation 0 0 1 -2.3561953071795863
      children [
        DEF track1-bounding Shape {
          appearance OsbWood {
          }
          geometry Box {
            size 1.2 0.006 0.05
          }
        }
      ]
      name "solid(7)"
      boundingObject USE track1-bounding
    }
    Solid {
      translation -1.82317 1.87238 0.02
      rotation 0 0 -1 8.23753e-07
      children [
        DEF track1-bounding Shape {
          appearance OsbWood {
          }
          geometry Box {
            size 1.2 0.006 0.05
          }
        }
      ]
      name "solid(8)"
      boundingObject USE track1-bounding
    }
    Solid {
      translation -0.441295 1.51579 0.02
      rotation 0 0 1 -0.785395307179586
      children [
        DEF track1-bounding Shape {
          appearance OsbWood {
          }
          geometry Box {
            size 0.6 0.006 0.05
          }
        }
      ]
      name "solid(9)"
      boundingObject USE track1-bounding
    }
    Solid {
      translation -0.0170328 -0.0963247 0.02
      rotation 0 0 1 -0.785395307179586
      children [
        DEF track1-bounding Shape {
          appearance OsbWood {
          }
          geometry Box {
            size 0.6 0.006 0.05
          }
        }
      ]
      name "solid(11)"
      boundingObject USE track1-bounding
    }
    Solid {
      translation -0.958482 -1.03777 0.02
      rotation 0 0 1 1.5708
      children [
        DEF track1-bounding Shape {
          appearance OsbWood {
          }
          geometry Box {
            size 0.61 0.006 0.05
          }
        }
      ]
      name "solid(24)"
      boundingObject USE track1-bounding
    }
    Solid {
      translation 0.395365 -0.453634 0.02
      rotation 0 0 -1 0.64
      children [
        DEF track1-bounding Shape {
          appearance OsbWood {
          }
          geometry Box {
            size 0.5 0.006 0.05
          }
        }
      ]
      name "solid(16)"
      boundingObject USE track1-bounding
    }
    Solid {
      translation 1.99704 -1.83922 0.02
      rotation 0 0 1 0.785401
      children [
        DEF track1-bounding Shape {
          appearance OsbWood {
          }
          geometry Box {
            size 0.6 0.006 0.05
          }
        }
      ]
      name "solid(12)"
      boundingObject USE track1-bounding
    }
    Solid {
      translation 1.99704 -0.821114 0.02
      rotation 0 0 1 2.3562
      children [
        DEF track1-bounding Shape {
          appearance OsbWood {
          }
          geometry Box {
            size 0.6 0.006 0.05
          }
        }
      ]
      name "solid(13)"
      boundingObject USE track1-bounding
    }
    Solid {
      translation 2.20704 -1.32969 0.02
      rotation 0 0 1 -1.5707953071795862
      children [
        DEF track1-bounding Shape {
          appearance OsbWood {
          }
          geometry Box {
            size 0.6 0.006 0.05
          }
        }
      ]
      name "solid(14)"
      boundingObject USE track1-bounding
    }
    Solid {
      translation -0.93594 1.80006 0.02
      rotation 0 0 -1 0.261797
      children [
        DEF track1-bounding Shape {
          appearance OsbWood {
          }
          geometry Box {
            size 0.6 0.006 0.05
          }
        }
      ]
      name "solid(10)"
      boundingObject USE track1-bounding
    }
    Solid {
      translation -0.23 0.71 0.02
      rotation 0 0 1 1.5708
      children [
        DEF track1-bounding Shape {
          appearance OsbWood {
          }
          geometry Box {
            size 1.2 0.006 0.05
          }
        }
      ]
      boundingObject USE track1-bounding
    }
    Solid {
      translation 1.19 -0.6 0.02
      rotation 0 0 -1 -5.307179586466759e-06
      children [
        DEF track1-bounding Shape {
          appearance OsbWood {
          }
          geometry Box {
            size 1.2 0.006 0.05
          }
        }
      ]
      name "solid(15)"
      boundingObject USE track1-bounding
    }
    Solid {
      translation 0.7 -1.34 0.02
      rotation 0 0 -1 -5.307179586466759e-06
      children [
        DEF track1-bounding Shape {
          appearance OsbWood {
          }
          geometry Box {
            size 1.2 0.006 0.05
          }
        }
      ]
      name "solid(17)"
      boundingObject USE track1-bounding
    }
    Solid {
      translation -0.5 -1.34 0.02
      rotation 0 0 -1 -5.307179586466759e-06
      children [
        DEF track1-bounding Shape {
          appearance OsbWood {
          }
          geometry Box {
            size 1.2 0.006 0.05
          }
        }
      ]
      name "solid(19)"
      boundingObject USE track1-bounding
    }
    Solid {
      translation -1.61052 -1.03948 0.02
      rotation 0 0 1 -0.523595307179586
      children [
        DEF track1-bounding Shape {
          appearance OsbWood {
          }
          geometry Box {
            size 1.2 0.006 0.05
          }
        }
      ]
      name "solid(20)"
      boundingObject USE track1-bounding
    }
    Solid {
      translation -2.14982 -0.13448 0.02
      rotation 0 0 1 1.5708
      children [
        DEF track1-bounding Shape {
          appearance OsbWood {
          }
          geometry Box {
            size 1.2 0.006 0.05
          }
        }
      ]
      name "solid(21)"
      boundingObject USE track1-bounding
    }
    Solid {
      translation -1.54982 0.46552 0.02
      rotation 0 0 1 -3.1415853071795863
      children [
        DEF track1-bounding Shape {
          appearance OsbWood {
          }
          geometry Box {
            size 1.2 0.006 0.05
          }
        }
      ]
      name "solid(22)"
      boundingObject USE track1-bounding
    }
    Solid {
      translation -0.95982 -0.13448 0.02
      rotation 0 0 -1 1.57079
      children [
        DEF track1-bounding Shape {
          appearance OsbWood {
          }
          geometry Box {
            size 1.2 0.006 0.05
          }
        }
      ]
      name "solid(23)"
      boundingObject USE track1-bounding
    }
    Solid {
      translation 1.19 -0.6 0.02
      rotation 0 0 -1 -5.307179586466759e-06
      children [
        DEF track1-bounding Shape {
          appearance OsbWood {
          }
          geometry Box {
            size 1.2 0.006 0.05
          }
        }
      ]
      name "solid(18)"
      boundingObject USE track1-bounding
    }
  ]
}
